<?xml version="1.0" encoding="utf-8"?>
<!-- =================================================================================== -->
<!-- |    This document was autogenerated by xacro from niryo_one.urdf.xacro           | -->
<!-- |    EDITING THIS FILE BY HAND IS NOT RECOMMENDED                                 | -->
<!-- =================================================================================== -->
<!--
    niryo_one.urdf.xacro
    Copyright (C) 2017 Niryo
    All rights reserved.

    This program is free software: you can redistribute it and/or modify
    it under the terms of the GNU General Public License as published by
    the Free Software Foundation, either version 3 of the License, or
    (at your option) any later version.

    This program is distributed in the hope that it will be useful,
    but WITHOUT ANY WARRANTY; without even the implied warranty of
    MERCHANTABILITY or FITNESS FOR A PARTICULAR PURPOSE.  See the
    GNU General Public License for more details.

    You should have received a copy of the GNU General Public License
    along with this program.  If not, see <http://www.gnu.org/licenses/>.
-->
<robot name="niryo_one">
  <!-- Properties -->
  <!-- Links -->
  <link name="world"/>
  <link name="base_link">
    <visual>
      <origin rpy="0 0 0" xyz="0 0 0"/>
      <geometry>
        <mesh filename="package://niryo_one_urdf/meshes/collada/base_link.dae"/>
      </geometry>
    </visual>
    <collision>
      <origin rpy="0 0 0" xyz="0 0 0"/>
      <geometry>
        <mesh filename="package://niryo_one_urdf/meshes/stl/base_link.stl"/>
      </geometry>
    </collision>
  </link>
  <link name="shoulder_link">
    <visual>
      <origin rpy="0 0 0" xyz="0 0 0"/>
      <geometry>
        <mesh filename="package://niryo_one_urdf/meshes/collada/shoulder_link.dae"/>
      </geometry>
    </visual>
    <collision>
      <origin rpy="0 0 0" xyz="0 0 0"/>
      <geometry>
        <mesh filename="package://niryo_one_urdf/meshes/stl/shoulder_link.stl"/>
      </geometry>
    </collision>
  </link>
  <link name="arm_link">
    <visual>
      <origin rpy="0 0 0" xyz="0 0 0"/>
      <geometry>
        <mesh filename="package://niryo_one_urdf/meshes/collada/arm_link.dae"/>
      </geometry>
    </visual>
    <collision>
      <origin rpy="0 0 0" xyz="0 0 0"/>
      <geometry>
        <mesh filename="package://niryo_one_urdf/meshes/stl/arm_link.stl"/>
      </geometry>
    </collision>
  </link>
  <link name="elbow_link">
    <visual>
      <origin rpy="0 0 0" xyz="0 0 0"/>
      <geometry>
        <mesh filename="package://niryo_one_urdf/meshes/collada/elbow_link.dae"/>
      </geometry>
    </visual>
    <collision>
      <origin rpy="0 0 0" xyz="0 0 0"/>
      <geometry>
        <mesh filename="package://niryo_one_urdf/meshes/stl/elbow_link.stl"/>
      </geometry>
    </collision>
  </link>
  <link name="forearm_link">
    <visual>
      <origin rpy="0 0 0" xyz="0 0 0"/>
      <geometry>
        <mesh filename="package://niryo_one_urdf/meshes/collada/forearm_link.dae"/>
      </geometry>
    </visual>
    <collision>
      <origin rpy="0 0 0" xyz="0 0 0"/>
      <geometry>
        <mesh filename="package://niryo_one_urdf/meshes/stl/forearm_link.stl"/>
      </geometry>
    </collision>
  </link>
  <link name="wrist_link">
    <visual>
      <origin rpy="0 0 0" xyz="0 0 0"/>
      <geometry>
        <mesh filename="package://niryo_one_urdf/meshes/collada/wrist_link.dae"/>
      </geometry>
    </visual>
    <collision>
      <origin rpy="0 0 0" xyz="0 0 0"/>
      <geometry>
        <mesh filename="package://niryo_one_urdf/meshes/stl/wrist_link.stl"/>
      </geometry>
    </collision>
  </link>
  <link name="hand_link">
    <visual>
      <origin rpy="0 0 0" xyz="0 0 0"/>
      <geometry>
        <mesh filename="package://niryo_one_urdf/meshes/collada/hand_link.dae"/>
      </geometry>
    </visual>
    <collision>
      <origin rpy="0 0 0" xyz="0 0 0"/>
      <geometry>
        <mesh filename="package://niryo_one_urdf/meshes/stl/hand_link.stl"/>
      </geometry>
    </collision>
  </link>

  <link name="tool_link">
</link>

<link name="gripper_base">
    <visual>
      <origin rpy="0 0 0" xyz="0 0 0"/>
      <geometry>
        <mesh filename="package://niryo_one_urdf/Gripper1/G1_MainSupport.STL" scale = ".001 .001 .001" />
      </geometry>
    </visual>
    <collision>
      <origin rpy="0 0 0" xyz="0 0 0"/>
      <geometry>
        <mesh filename="package://niryo_one_urdf/Gripper1/G1_MainSupport.STL" scale = ".001 .001 .001" />
      </geometry>
    </collision>

  </link>
  <link name="servo_head">
    <visual>
      <origin rpy="0 0 0" xyz="0 0 0"/>
      <geometry>
        <mesh filename="package://niryo_one_urdf/Gripper1/G1_ServoHead.STL" scale = ".001 .001 .001"/>
      </geometry>
    </visual>
    <collision>
      <origin rpy="0 0 0" xyz="0 0 0"/>
      <geometry>
        <mesh filename="package://niryo_one_urdf/Gripper1/G1_ServoHead.STL" scale = ".001 .001 .001"/>
      </geometry>
    </collision>

  </link>

  <link name="control_rod_right">
    <visual>
      <origin rpy="0 0 0" xyz="0 0 0"/>
      <geometry>
        <mesh filename="package://niryo_one_urdf/Gripper1/G1_Rod.STL" scale = ".001 .001 .001"/>
      </geometry>
    </visual>
    <collision>
      <origin rpy="0 0 0" xyz="0 0 0"/>
      <geometry>
        <mesh filename="package://niryo_one_urdf/Gripper1/G1_Rod.STL" scale = ".001 .001 .001"/>
      </geometry>
    </collision>
  </link>

  <link name="control_rod_left">
    <visual>
      <origin rpy="0 0 0" xyz="0 0 0"/>
      <geometry>
        <mesh filename="package://niryo_one_urdf/Gripper1/G1_Rod.STL" scale = ".001 .001 .001"/>
      </geometry>
    </visual>
    <collision>
      <origin rpy="0 0 0" xyz="0 0 0"/>
      <geometry>
        <mesh filename="package://niryo_one_urdf/Gripper1/G1_Rod.STL" scale = ".001 .001 .001"/>
      </geometry>
    </collision>
  </link>

<link name="right_gripper">
    <visual>
      <origin rpy="0 0 0" xyz="0 0 0"/>
      <geometry>
        <mesh filename="package://niryo_one_urdf/Gripper1/G1_ClampRight.STL" scale = ".001 .001 .001"/>
      </geometry>
    </visual>
    <collision>
      <origin rpy="0 0 0" xyz="0 0 0"/>
      <geometry>
        <mesh filename="package://niryo_one_urdf/Gripper1/G1_ClampRight.STL" scale = ".001 .001 .001"/>
      </geometry>
    </collision>

  </link>
<link name="left_gripper">
    <visual>
      <origin rpy="0 0 0" xyz="0 0 0"/>
      <geometry>
        <mesh filename="package://niryo_one_urdf/Gripper1/G1_ClampLeft.STL" scale = ".001 .001 .001"/>
      </geometry>
    </visual>
    <collision>
      <origin rpy="0 0 0" xyz="0 0 0"/>
      <geometry>
        <mesh filename="package://niryo_one_urdf/Gripper1/G1_ClampLeft.STL" scale = ".001 .001 .001"/>
      </geometry>
    </collision>

  </link>

  <!--Disable_Collisions -->
  <disable_collision link1="right_gripper" link2="gripper_base">
  </disable_collision>
  <disable_collision link1="left_gripper" link2="gripper_base">
  </disable_collision>

  <!--Joints -->
  <joint name="joint_world" type="fixed">
    <parent link="world"/>
    <child link="base_link"/>
    <origin rpy="0 0 0" xyz="0 0 0.63"/>
  </joint>
  <joint name="joint_1" type="revolute">
    <parent link="base_link"/>
    <child link="shoulder_link"/>
    <origin rpy="0 0 0" xyz="0 0 0.103"/>
    <axis xyz="0 0 1"/>
    <limit effort="1" lower="-3.05433" upper="3.05433" velocity="1.0"/>
  </joint>
  <joint name="joint_2" type="revolute">
    <parent link="shoulder_link"/>
    <child link="arm_link"/>
    <origin rpy="1.5707963268 -1.5707963268 0" xyz="0 0 0.08"/>
    <limit effort="1" lower="-1.91986" upper="0.640187" velocity="1.0"/>
    <axis xyz="0 0 1"/>
  </joint>
  <joint name="joint_3" type="revolute">
    <parent link="arm_link"/>
    <child link="elbow_link"/>
    <origin rpy="0 0 -1.5707963268" xyz="0.21 0.0 0"/>
    <limit effort="1" lower="-1.397485" upper="1.5707963268" velocity="1.0"/>
    <axis xyz="0 0 1"/>
  </joint>
  <joint name="joint_4" type="revolute">
    <parent link="elbow_link"/>
    <child link="forearm_link"/>
    <origin rpy="0 1.5707963268 0" xyz="0.0415 0.03 0"/>
    <limit effort="1" lower="-3.05433" upper="3.05433" velocity="1.0"/>
    <axis xyz="0 0 1"/>
  </joint>
  <joint name="joint_5" type="revolute">
    <parent link="forearm_link"/>
    <child link="wrist_link"/>
    <origin rpy="0 -1.5707963268 0" xyz="0 0 0.18"/>
    <limit effort="1" lower="-1.74533" upper="1.91986" velocity="1.0"/>
    <axis xyz="0 0 1"/>
  </joint>
  <joint name="joint_6" type="revolute">
    <parent link="wrist_link"/>
    <child link="hand_link"/>
    <origin rpy="0 1.5707963268 0" xyz="0.0164 -0.0055 0"/>
    <limit effort="1" lower="-2.57436" upper="2.57436" velocity="1.0"/>
    <axis xyz="0 0 1"/>
  </joint>
  <joint name="hand_tool_joint" type="fixed">
    <parent link="hand_link"/>
    <child link="tool_link"/>
    <origin rpy="-1.5707963268 -1.5707963268 0" xyz="0 0 0.0073"/>
  </joint>

  <joint name="hand_tool_joint" type="fixed">
    <parent link="tool_link"/>
    <child link="gripper_base"/>
    <origin rpy="1.5707 0 -1.5707" xyz="0.0246 0 -0.01475"/>
  </joint>

  <joint name="servo_head_joint" type="fixed">
    <parent link="gripper_base"/>
    <child link="servo_head"/>
    <origin rpy="0 0 0" xyz="0 0 0"/>
  </joint>
  <joint name="control_rod_left" type="fixed">
    <parent link="servo_head"/>
    <child link="control_rod_left"/>
    <origin rpy="0 0 0" xyz="0 0 0"/>
  </joint>
<joint name="control_rod_right" type="fixed">
    <parent link="servo_head"/>
    <child link="control_rod_right"/>
    <origin rpy="0 3.141 0" xyz="0 0 0"/>
  </joint>
  <joint name="gripper_joint_right" type="prismatic">
    <parent link="control_rod_right"/>
    <child link="right_gripper"/>
    <origin rpy="0 3.141 0" xyz="0 0 0"/>
    <limit effort="1" lower="-0.0257436" upper="0.0257436" velocity="1.0"/>
    <mimic joint = "gripper_joint_left" multiplier = "-1"/> 
  </joint>
<joint name="gripper_joint_left" type="prismatic">
    <parent link="control_rod_left"/>
    <child link="left_gripper"/>
    <origin rpy="0 0 0" xyz="0 0 0"/>
    <limit effort="1" lower="-0.0257436" upper="0.0257436" velocity="1.0"/>
  </joint>
</robot>

